Workbook
Name ACTIVE_RAID: Model!$B$31
Name AEGIS_ALLOWED: Model!$B$166
Name AEGIS_CELL_SLACK: Model!$B$61
Name AEGIS_CELLS_USED: Model!$B$60
Name AEGIS_SITES: Model!$B$103
Name ALL_VALID: Model!$B$89
Name ALLOWED: Model!$B$157:$G$159
Name ALLOWED_NOW: Model!$B$160:$G$160
Name BUDGET: Model!$B$23
Name BUILD_AEGIS: Model!$B$41
Name BUILD_THAAD: Model!$D$41
Name CAP: Model!$B$13:$G$13
Name CAP_SLACK: Model!$B$67:$G$67
Name COVERED_FRACTION: Model!$B$116
Name D: Model!$B$50:$E$50
Name D_COVERED: Model!$B$125:$E$125
Name D_UNCOVERED: Model!$B$126:$E$126
Name EFF_COVERED: Model!$B$123:$E$123
Name EFF_UNCOVERED: Model!$B$124:$E$124
Name FLOOR: Model!$B$18:$E$18
Name INTERCEPTOR_SPEND: Model!$B$55
Name KRATE: Model!$B$147:$G$150
Name MIN_REQUIRED: Model!$B$52:$E$52
Name MK41_CELLS: Model!$B$28
Name MSE_CAP: Model!$C$13
Name MSE_FULL_SLACK: Model!$B$167
Name MSE_PK_ABT: Model!$C$11
Name MSE_PK_BM: Model!$C$9
Name MSE_PK_CM: Model!$C$10
Name MSE_PK_UAS: Model!$C$12
Name MSE_PRICE: Model!$C$7
Name MSE_Q: Model!$C$45
Name MSE_SYSTEM: Model!$C$8
Name OPTION: Model!$B$154
Name PAC3_CAP: Model!$B$13
Name PAC3_PK_ABT: Model!$B$11
Name PAC3_PK_BM: Model!$B$9
Name PAC3_PK_CM: Model!$B$10
Name PAC3_PK_UAS: Model!$B$12
Name PAC3_PRICE: Model!$B$7
Name PAC3_Q: Model!$B$45
Name PAC3_SYSTEM: Model!$B$8
Name PATRIOT_BATTERIES: Model!$C$41
Name PATRIOT_LAUNCHERS: Model!$B$29
Name PATRIOT_LAUNCHERS_USED: Model!$B$62
Name PATRIOT_MAX: Model!$B$102
Name PATRIOT_MAX_NOW: Model!$B$165
Name PATRIOT_MIN: Model!$B$164
Name PATRIOT_SITES_COVERED: Model!$B$115
Name PATRIOT_SLACK: Model!$B$63
Name PK_ABT: Model!$B$11:$G$11
Name PK_BM: Model!$B$9:$G$9
Name PK_CM: Model!$B$10:$G$10
Name PK_UAS: Model!$B$12:$G$12
Name PRICE: Model!$B$7:$G$7
Name PROTECTION: Model!$B$65
Name Q_TOTAL: Model!$B$45:$G$45
Name QC: Model!$B$108:$G$111
Name QC_SLACK: Model!$B$118
Name QU: Model!$B$35:$G$38

Sheet Model
A1: Guam interceptor loadout - economic research model (inputs from Table 1 of the paper, 2026-10-10; site constraints, kill rate and options added)
A2: Built from capabilities/economic-research/spec.md. Blue = input (all DRAFT placeholders until sourced). Yellow = decision cell (Solver changes these). Black = formula. Money in USD millions ($M).
A3: HOW TO USE: set OPTION, ACTIVE_RAID and BUDGET, then Data > Solver > Solve (the Solver setup is saved in this sheet). Inputs are from Table 1 of the paper; kill probabilities, raid sizes, weights and the even spread over 16 sites are placeholders. Site constraints are in rows 98-143; options in rows 152-175.
A5: INPUTS - per interceptor (DRAFT: secondary-source ranges and placeholder assumptions)
A6: Name | B6: PAC-3 CRI | C6: PAC-3 MSE | D6: THAAD | E6: SM-3 IIA | F6: SM-2 | G6: SM-6 | H6: Unit | I6: Source / status
A7: PRICE | B7: 3.7 | C7: 4.2 | D7: 12.7 | E7: 27.9 | F7: 2.05 | G7: 6.55 | H7: $M per interceptor | I7: Table 1 (paper, 2026-10-09): CRI $3.7M, MSE $4.2M, THAAD $12.7M, SM-3 IIA $27.9M, SM-2 $2.0-2.1M and SM-6 $3.5-9.6M (midpoints used for the two ranges). NOT yet confirmed against budget books or contract awards; see the paper's price notes.
A8: SYSTEM | B8: PATRIOT | C8: PATRIOT | D8: THAAD | E8: AEGIS | F8: AEGIS | G8: AEGIS | H8: text | I8: Which launcher system each interceptor needs
A9: PK_BM | B9: 0.5 | C9: 0.5 | D9: 0.5 | E9: 0.5 | F9: 0 | G9: 0.5 | H9: single-shot kill prob. | I9: Single-shot kill probability: 50% baseline (PLACEHOLDER) wherever Table 1 lists the threat for that interceptor; 0 = cannot engage. n shots at one threat kill it with probability 1 - (1 - PK)^n (see KRATE). Row BM.
A10: PK_CM | B10: 0.5 | C10: 0.5 | D10: 0 | E10: 0 | F10: 0.5 | G10: 0.5 | H10: single-shot kill prob. | I10: Single-shot kill probability: 50% baseline (PLACEHOLDER) wherever Table 1 lists the threat for that interceptor; 0 = cannot engage. n shots at one threat kill it with probability 1 - (1 - PK)^n (see KRATE).
A11: PK_ABT | B11: 0.5 | C11: 0.5 | D11: 0 | E11: 0 | F11: 0.5 | G11: 0.5 | H11: single-shot kill prob. | I11: Single-shot kill probability: 50% baseline (PLACEHOLDER) wherever Table 1 lists the threat for that interceptor; 0 = cannot engage. n shots at one threat kill it with probability 1 - (1 - PK)^n (see KRATE).
A12: PK_UAS | B12: 0 | C12: 0 | D12: 0 | E12: 0 | F12: 0 | G12: 0.5 | H12: single-shot kill prob. | I12: Single-shot kill probability: 50% baseline (PLACEHOLDER) wherever Table 1 lists the threat for that interceptor; 0 = cannot engage. n shots at one threat kill it with probability 1 - (1 - PK)^n (see KRATE).
A13: CAP | B13: 2000 | C13: 2000 | D13: 2000 | E13: 2000 | F13: 2000 | G13: 2000 | H13: interceptors through FY2032 | I13: PLACEHOLDER (non-binding): no Table 2 result buys more than 615 of one type. Replace with production rate x years.
A15: INPUTS - per threat class
A16: Name | B16: BM | C16: CM | D16: ABT | E16: UAS | H16: Unit | I16: Source / status
A17: W | B17: 10 | C17: 5 | D17: 4 | E17: 1 | H17: damage weight (index) | I17: PLACEHOLDER judgment: relative damage of one leaked threat. Vary in sensitivity runs.
A18: FLOOR | B18: 0 | C18: 0 | D18: 0 | E18: 0 | H18: share of class defeated | I18: Policy choice: minimum share of each class that must be defeated (0 = no floor).
A19: R (active raid) | B19: =INDEX(Scenarios!B$5:B$7,MATCH(ACTIVE_RAID,Scenarios!$A$5:$A$7,0)) -> 40 | C19: =INDEX(Scenarios!C$5:C$7,MATCH(ACTIVE_RAID,Scenarios!$A$5:$A$7,0)) -> 30 | D19: =INDEX(Scenarios!D$5:D$7,MATCH(ACTIVE_RAID,Scenarios!$A$5:$A$7,0)) -> 10 | E19: =INDEX(Scenarios!E$5:E$7,MATCH(ACTIVE_RAID,Scenarios!$A$5:$A$7,0)) -> 50 | H19: threats in raid | I19: Pulled from the Scenarios sheet for ACTIVE_RAID.
A21: INPUTS - the named contract (scalars)
A22: Name | B22: Value | H22: Unit | I22: Source / status
A23: BUDGET | B23: 8000 | H23: $M | I23: The roughly $8B Guam Defense System cap (Arms Control Association, 2025), used as the interceptor and system budget. PLACEHOLDER: the interceptor share is not sourced.
A24: USE_MIN | B24: 0 | H24: fraction of BUDGET | I24: 0 = spend only what buys protection; 0.98 = "use the whole budget" run (spec: two runs).
A25: SYS_COST_AEGIS | B25: 1900 | H25: $M, one system | I25: Table 1: Aegis Guam $1.9B (Brahy, 2026). Note: one report describes $1.9B as the cumulative value of a broader Aegis contract, not a Guam-only cost.
A26: SYS_COST_PATRIOT | B26: 400 | H26: $M, one battery | I26: Table 1: Patriot battery about $0.4B without missiles. Supported by a secondary source citing CRS; not confirmed to a budget book. Counted once per battery.
A27: SYS_COST_THAAD | B27: 0 | H27: $M | I27: THAAD battery already deployed on Guam since 2013: a sunk cost, so 0 here. Only new interceptors cost money.
A28: MK41_CELLS | B28: 96 | H28: launcher cells | I28: PLACEHOLDER (Table 1 dagger). Aegis Guam Mk 41 cell count not yet sourced. Shared by SM-2, SM-3, SM-6.
A29: PATRIOT_LAUNCHERS | B29: 6 | H29: M903 launchers | I29: Nominal battery of 6 launchers; each holds 16 PAC-3 CRI or 12 PAC-3 MSE (Wikipedia, MIM-104 Patriot).
A30: THAAD_CAP | B30: 48 | H30: interceptors | I30: Battery of 6 launchers x 8 (user input). Assumes one load for the existing battery.
A31: ACTIVE_RAID | B31: A ballistic-heavy | H31: scenario name | I31: Pick a row name from the Scenarios sheet.
A33: DECISION VARIABLES - integers; Solver 'By Changing Variable Cells'
A34: QU (interceptors at sites WITHOUT Patriot cover) | B34: PAC-3 CRI | C34: PAC-3 MSE | D34: THAAD | E34: SM-3 IIA | F34: SM-2 | G34: SM-6 | H34: Unit | I34: Constraint
A35: QU_BM | B35: 0 | C35: 0 | D35: 0 | E35: 0 | F35: 0 | G35: 0 | H35: interceptors | I35: integer >= 0; assigning a type to a class where its PK = 0 buys nothing. Patriot columns (B:C) must be 0 here: Patriot only defends the sites its batteries cover (use the QC grid, row 108 onward)
A36: QU_CM | B36: 0 | C36: 0 | D36: 0 | E36: 0 | F36: 0 | G36: 0 | H36: interceptors | I36: integer >= 0; assigning a type to a class where its PK = 0 buys nothing. Patriot columns (B:C) must be 0 here: Patriot only defends the sites its batteries cover (use the QC grid, row 108 onward)
A37: QU_ABT | B37: 0 | C37: 0 | D37: 0 | E37: 0 | F37: 0 | G37: 0 | H37: interceptors | I37: integer >= 0; assigning a type to a class where its PK = 0 buys nothing. Patriot columns (B:C) must be 0 here: Patriot only defends the sites its batteries cover (use the QC grid, row 108 onward)
A38: QU_UAS | B38: 0 | C38: 0 | D38: 0 | E38: 0 | F38: 0 | G38: 0 | H38: interceptors | I38: integer >= 0; assigning a type to a class where its PK = 0 buys nothing. Patriot columns (B:C) must be 0 here: Patriot only defends the sites its batteries cover (use the QC grid, row 108 onward)
A40: BUILD (Aegis, THAAD: 1 = buy; Patriot: number of batteries) | B40: AEGIS | C40: PATRIOT (batteries) | D40: THAAD | H40: Unit | I40: Constraint
A41: BUILD | B41: 1 | C41: 8 | D41: 1 | H41: 0/1; Patriot 0 to PATRIOT_MAX | I41: Aegis and THAAD: binary, a system cost is paid once (fixed vs. marginal cost). Patriot (PATRIOT_BATTERIES): whole number 0 to PATRIOT_MAX; each battery costs SYS_COST_PATRIOT, has PATRIOT_LAUNCHERS launchers, and defends SITES_PER_PATRIOT sites
A43: CALCULATIONS - totals, protection, spending
A44: Name | B44: PAC-3 CRI | C44: PAC-3 MSE | D44: THAAD | E44: SM-3 IIA | F44: SM-2 | G44: SM-6 | H44: Unit | I44: Formula (named-range form)
A45: Q_TOTAL | B45: =SUM(B35:B38)+SUM(B108:B111) -> 322 | C45: =SUM(C35:C38)+SUM(C108:C111) -> 257 | D45: =SUM(D35:D38)+SUM(D108:D111) -> 0 | E45: =SUM(E35:E38)+SUM(E108:E111) -> 0 | F45: =SUM(F35:F38)+SUM(F108:F111) -> 0 | G45: =SUM(G35:G38)+SUM(G108:G111) -> 96 | H45: interceptors | I45: Q_i = SUM over classes of QU_ij + QC_ij
A46: SPEND_BY_TYPE | B46: =B7*B45 -> 1191.4 | C46: =C7*C45 -> 1079.4 | D46: =D7*D45 -> 0 | E46: =E7*E45 -> 0 | F46: =F7*F45 -> 0 | G46: =G7*G45 -> 628.8 | H46: $M | I46: PRICE_i x Q_i
...

Sheet Table 2
A1: Table 2 of the paper: where each number comes from
A2: Each Table 2 cell is the PROTECTION cell (Model!B65) after setting OPTION (Model!B154), ACTIVE_RAID (Model!B31) and BUDGET (Model!B23 = 8,000) and solving. The reference values on the Scenarios sheet (rows 13-21) come from an external integer solver (reference-optimizer.py, in this folder); column E checks each of the paper's rounded values against them (FALSE = the paper's number differs from the workbook).
A3: Inputs are Table 1 of the paper; the 50% kill probability, raid sizes, damage weights and the even spread of threats over 16 sites are placeholders. Options 2 and 3 are re-solved for each raid; Option 1 is one fixed purchase.
A5: Option | B5: Raid | C5: Paper Table 2 (%) | D5: Workbook reference (%) | E5: Matches paper? | F5: Spend ($M) | G5: Protection points per $B | H5: How to reproduce
A6: =Scenarios!N13 -> 1 - 8 Patriot batteries, MSE only | B6: =Scenarios!B13 -> A ballistic-heavy | C6: 92 | D6: =Scenarios!C13*100 -> 91.564768 | E6: =ROUND(D6,0)=C6 -> TRUE | F6: =Scenarios!D13 -> 5619.2 | G6: =D6/(F6/1000) -> 16.294983 | H6: OPTION = 1, ACTIVE_RAID = A ballistic-heavy, BUDGET = 8000, USE_MIN = 0; solve; read Model!B65
A7: =Scenarios!N14 -> 1 - 8 Patriot batteries, MSE only | B7: =Scenarios!B14 -> B cruise-heavy | C7: 89 | D7: =Scenarios!C14*100 -> 88.496929 | E7: =ROUND(D7,0)=C7 -> FALSE | F7: =Scenarios!D14 -> 5619.2 | G7: =D7/(F7/1000) -> 15.749026 | H7: OPTION = 1, ACTIVE_RAID = B cruise-heavy, BUDGET = 8000, USE_MIN = 0; solve; read Model!B65
A8: =Scenarios!N15 -> 1 - 8 Patriot batteries, MSE only | B8: =Scenarios!B15 -> C drone saturation | C8: 49 | D8: =Scenarios!C15*100 -> 49.000734 | E8: =ROUND(D8,0)=C8 -> TRUE | F8: =Scenarios!D15 -> 5619.2 | G8: =D8/(F8/1000) -> 8.7202332 | H8: OPTION = 1, ACTIVE_RAID = C drone saturation, BUDGET = 8000, USE_MIN = 0; solve; read Model!B65
A9: =Scenarios!N16 -> 2 - current Guam plan | B9: =Scenarios!B16 -> A ballistic-heavy | C9: 68 | D9: =Scenarios!C16*100 -> 67.502195 | E9: =ROUND(D9,0)=C9 -> TRUE | F9: =Scenarios!D16 -> 4120.5 | G9: =D9/(F9/1000) -> 16.38204 | H9: OPTION = 2, ACTIVE_RAID = A ballistic-heavy, BUDGET = 8000, USE_MIN = 0; solve; read Model!B65
A10: =Scenarios!N17 -> 2 - current Guam plan | B10: =Scenarios!B17 -> B cruise-heavy | C10: 53 | D10: =Scenarios!C17*100 -> 53.314099 | E10: =ROUND(D10,0)=C10 -> TRUE | F10: =Scenarios!D17 -> 3138.4 | G10: =D10/(F10/1000) -> 16.987668 | H10: OPTION = 2, ACTIVE_RAID = B cruise-heavy, BUDGET = 8000, USE_MIN = 0; solve; read Model!B65
A11: =Scenarios!N18 -> 2 - current Guam plan | B11: =Scenarios!B18 -> C drone saturation | C11: 43 | D11: =Scenarios!C18*100 -> 42.504532 | E11: =ROUND(D11,0)=C11 -> TRUE | F11: =Scenarios!D18 -> 3138.4 | G11: =D11/(F11/1000) -> 13.543376 | H11: OPTION = 2, ACTIVE_RAID = C drone saturation, BUDGET = 8000, USE_MIN = 0; solve; read Model!B65
A12: =Scenarios!N19 -> 3 - optimal mix (up to 8 batteries) | B12: =Scenarios!B19 -> A ballistic-heavy | C12: 97 | D12: =Scenarios!C19*100 -> 97.322318 | E12: =ROUND(D12,0)=C12 -> TRUE | F12: =Scenarios!D19 -> 7999.6 | G12: =D12/(F12/1000) -> 12.165898 | H12: OPTION = 3, ACTIVE_RAID = A ballistic-heavy, BUDGET = 8000, USE_MIN = 0; solve; read Model!B65
A13: =Scenarios!N20 -> 3 - optimal mix (up to 8 batteries) | B13: =Scenarios!B20 -> B cruise-heavy | C13: 95 | D13: =Scenarios!C20*100 -> 94.901427 | E13: =ROUND(D13,0)=C13 -> TRUE | F13: =Scenarios!D20 -> 7999.8 | G13: =D13/(F13/1000) -> 11.862975 | H13: OPTION = 3, ACTIVE_RAID = B cruise-heavy, BUDGET = 8000, USE_MIN = 0; solve; read Model!B65
A14: =Scenarios!N21 -> 3 - optimal mix (up to 8 batteries) | B14: =Scenarios!B21 -> C drone saturation | C14: 59 | D14: =Scenarios!C21*100 -> 58.955298 | E14: =ROUND(D14,0)=C14 -> TRUE | F14: =Scenarios!D21 -> 7616.6 | G14: =D14/(F14/1000) -> 7.7403694 | H14: OPTION = 3, ACTIVE_RAID = C drone saturation, BUDGET = 8000, USE_MIN = 0; solve; read Model!B65
A16: ALL NINE MATCH | E16: =AND(E6:E14) -> FALSE
A18: Table 2 spend column
A19: Option | B19: Paper low ($B) | C19: Paper high ($B) | D19: Workbook low ($B) | E19: Workbook high ($B) | F19: Matches paper?
A20: =A6 -> 1 - 8 Patriot batteries, MSE only | B20: 5.6 | C20: 5.6 | D20: =ROUND(MIN(F6:F8)/1000,1) -> 5.6 | E20: =ROUND(MAX(F6:F8)/1000,1) -> 5.6 | F20: =AND(D20=B20,E20=C20) -> TRUE
A21: =A9 -> 2 - current Guam plan | B21: 3.1 | C21: 4.1 | D21: =ROUND(MIN(F9:F11)/1000,1) -> 3.1 | E21: =ROUND(MAX(F9:F11)/1000,1) -> 4.1 | F21: =AND(D21=B21,E21=C21) -> TRUE
A22: =A12 -> 3 - optimal mix (up to 8 batteries) | B22: 7.6 | C22: 8 | D22: =ROUND(MIN(F12:F14)/1000,1) -> 7.6 | E22: =ROUND(MAX(F12:F14)/1000,1) -> 8 | F22: =AND(D22=B22,E22=C22) -> TRUE
A25: MOST BANG FOR THE BUCK: best protection (Option 3, unrestricted) at each budget, per raid
A26: Hardcoded values from the same external solver (reference-optimizer.py), not Excel Solver. Protection points per $B = protection (%) / spend ($B). Extra points per extra $B = change from the previous budget for the same raid. Compare Options 1 and 2 above (points per $B in column G).
A27: Budget ($M) | B27: Raid | C27: Protection (%) | D27: Spend ($M) | E27: Protection points per $B | F27: Extra points per extra $B | G27: Patriot batteries | H27: Aegis built
A28: 2000 | B28: A ballistic-heavy | C28: 55.536 | D28: 1998.7 | E28: =C28/(D28/1000) -> 27.786061 | G28: 3 | H28: 0
A29: 2000 | B29: B cruise-heavy | C29: 41.706 | D29: 1999 | E29: =C29/(D29/1000) -> 20.863432 | G29: 3 | H29: 0
A30: 2000 | B30: C drone saturation | C30: 28.375 | D30: 1999.1 | E30: =C30/(D30/1000) -> 14.193887 | G30: 3 | H30: 0
A31: 3000 | B31: A ballistic-heavy | C31: 70.349 | D31: 2997.7 | E31: =C31/(D31/1000) -> 23.467659 | F31: =(C31-C28)/((D31-D28)/1000) -> 14.827828 | G31: 4 | H31: 0
A32: 3000 | B32: B cruise-heavy | C32: 57.333 | D32: 2999.7 | E32: =C32/(D32/1000) -> 19.112911 | F32: =(C32-C29)/((D32-D29)/1000) -> 15.616069 | G32: 5 | H32: 0
A33: 3000 | B33: C drone saturation | C33: 43.46 | D33: 2999.6 | E33: =C33/(D33/1000) -> 14.488598 | F33: =(C33-C30)/((D33-D30)/1000) -> 15.077461 | G33: 1 | H33: 1
A34: 4000 | B34: A ballistic-heavy | C34: 82.464 | D34: 3999 | E34: =C34/(D34/1000) -> 20.621155 | F34: =(C34-C31)/((D34-D31)/1000) -> 12.099271 | G34: 7 | H34: 0
A35: 4000 | B35: B cruise-heavy | C35: 72.916 | D35: 3999.9 | E35: =C35/(D35/1000) -> 18.229456 | F35: =(C35-C32)/((D35-D32)/1000) -> 15.579884 | G35: 7 | H35: 0
A36: 4000 | B36: C drone saturation | C36: 47.492 | D36: 3999.5 | E36: =C36/(D36/1000) -> 11.874484 | F36: =(C36-C33)/((D36-D33)/1000) -> 4.0324032 | G36: 3 | H36: 1
A37: 5000 | B37: A ballistic-heavy | C37: 90.806 | D37: 4998.2 | E37: =C37/(D37/1000) -> 18.16774 | F37: =(C37-C34)/((D37-D34)/1000) -> 8.3486789 | G37: 8 | H37: 0
A38: 5000 | B38: B cruise-heavy | C38: 86.616 | D38: 4998.2 | E38: =C38/(D38/1000) -> 17.329439 | F38: =(C38-C35)/((D38-D35)/1000) -> 13.72333 | G38: 8 | H38: 0
A39: 5000 | B39: C drone saturation | C39: 51.335 | D39: 4999.1 | E39: =C39/(D39/1000) -> 10.268848 | F39: =(C39-C36)/((D39-D36)/1000) -> 3.8445378 | G39: 5 | H39: 1
A40: 5619 | B40: A ballistic-heavy | C40: 91.574 | D40: 5378.8 | E40: =C40/(D40/1000) -> 17.024987 | F40: =(C40-C37)/((D40-D37)/1000) -> 2.0178665 | G40: 8 | H40: 0
A41: 5619 | B41: B cruise-heavy | C41: 89.571 | D41: 5616.1 | E41: =C41/(D41/1000) -> 15.948968 | F41: =(C41-C38)/((D41-D38)/1000) -> 4.7823272 | G41: 8 | H41: 0
A42: 5619 | B42: C drone saturation | C42: 53.998 | D42: 5618 | E42: =C42/(D42/1000) -> 9.6116056 | F42: =(C42-C39)/((D42-D39)/1000) -> 4.3027953 | G42: 6 | H42: 1
... A51: 8000 | B51: C drone saturation | C51: 58.955 | D51: 7616.6 | E51: =C51/(D51/1000) -> 7.7403303 | F51: =(C51-C48)/((D51-D48)/1000) -> 0.20203653 | G51: 8 | H51: 1

Sheet Scenarios
A1: Raid scenarios and results log
A2: Raid sizes are PLACEHOLDERS. Spec: hold attacker spending constant and change only the split, so cheaper threats appear as larger raids.
A4: Scenario | B4: BM | C4: CM | D4: ABT | E4: UAS | F4: Note
A5: A ballistic-heavy | B5: 40 | C5: 30 | D5: 10 | E5: 50 | F5: mostly medium/intermediate-range ballistic missiles
A6: B cruise-heavy | B6: 15 | C6: 80 | D6: 20 | E6: 60 | F6: mostly cruise missiles and aircraft
A7: C drone saturation | B7: 10 | C7: 30 | D7: 10 | E7: 300 | F7: mostly cheap one-way attack drones
A10: REFERENCE RESULTS - the nine Table 2 cells (Python integer optimizer, same inputs, OPTION x raid, BUDGET = 8,000, USE_MIN = 0)
A11: Hardcoded values from an external solver, for checking Excel Solver only. Set OPTION and ACTIVE_RAID, then solve. Solver should reach the same PROTECTION within ~0.5 points; different mixes can tie, so compare PROTECTION and spend, not exact quantities.
A12: Budget ($M) | B12: Scenario | C12: Protection | D12: Spent ($M) | E12: Aegis built | F12: Patriot batteries | G12: PAC-3 CRI | H12: PAC-3 MSE | I12: THAAD | J12: SM-3 IIA | K12: SM-2 | L12: SM-6 | M12: Patriot sites | N12: Option
A13: 8000 | B13: A ballistic-heavy | C13: 0.91564768 | D13: 5619.2 | E13: 0 | F13: 8 | G13: 0 | H13: 576 | I13: 0 | J13: 0 | K13: 0 | L13: 0 | M13: 16 | N13: 1 - 8 Patriot batteries, MSE only
A14: 8000 | B14: B cruise-heavy | C14: 0.88496929 | D14: 5619.2 | E14: 0 | F14: 8 | G14: 0 | H14: 576 | I14: 0 | J14: 0 | K14: 0 | L14: 0 | M14: 16 | N14: 1 - 8 Patriot batteries, MSE only
A15: 8000 | B15: C drone saturation | C15: 0.49000734 | D15: 5619.2 | E15: 0 | F15: 8 | G15: 0 | H15: 576 | I15: 0 | J15: 0 | K15: 0 | L15: 0 | M15: 16 | N15: 1 - 8 Patriot batteries, MSE only
A16: 8000 | B16: A ballistic-heavy | C16: 0.67502195 | D16: 4120.5 | E16: 1 | F16: 0 | G16: 0 | H16: 0 | I16: 48 | J16: 46 | K16: 0 | L16: 50 | M16: 0 | N16: 2 - current Guam plan
A17: 8000 | B17: B cruise-heavy | C17: 0.53314099 | D17: 3138.4 | E17: 1 | F17: 0 | G17: 0 | H17: 0 | I17: 48 | J17: 0 | K17: 0 | L17: 96 | M17: 0 | N17: 2 - current Guam plan
A18: 8000 | B18: C drone saturation | C18: 0.42504532 | D18: 3138.4 | E18: 1 | F18: 0 | G18: 0 | H18: 0 | I18: 48 | J18: 0 | K18: 0 | L18: 96 | M18: 0 | N18: 2 - current Guam plan
A19: 8000 | B19: A ballistic-heavy | C19: 0.97322318 | D19: 7999.6 | E19: 1 | F19: 8 | G19: 322 | H19: 257 | I19: 0 | J19: 0 | K19: 0 | L19: 96 | M19: 16 | N19: 3 - optimal mix (up to 8 batteries)
A20: 8000 | B20: B cruise-heavy | C20: 0.94901427 | D20: 7999.8 | E20: 1 | F20: 8 | G20: 615 | H20: 0 | I20: 0 | J20: 0 | K20: 1 | L20: 95 | M20: 16 | N20: 3 - optimal mix (up to 8 batteries)
A21: 8000 | B21: C drone saturation | C21: 0.58955298 | D21: 7616.6 | E21: 1 | F21: 8 | G21: 98 | H21: 218 | I21: 48 | J21: 0 | K21: 0 | L21: 96 | M21: 16 | N21: 3 - optimal mix (up to 8 batteries)
A24: Source: scipy.optimize.milp run by Claude on 2026-10-10 with the Model sheet inputs as built (Table 1 prices, 50% single-shot kill probability in the salvo form, 16 sites, up to 8 Patriot batteries at 2 sites each); tangent-line approximation of D, protection re-evaluated exactly. These are the nine cells of Table 2 in the paper (92 / 89 / 49, 68 / 53 / 43, 97 / 95 / 59 percent). Illustrative only.
A26: MY SOLVER RUNS - record each Excel Solver result here
A27: Budget ($M) | B27: Scenario | C27: USE_MIN | D27: Protection | E27: Spent ($M) | F27: Matches reference? | G27: Notes

Sheet Solver Model
A1: Solver setup (saved in the Model sheet; open Data > Solver to see it)
A3: Objective | B3: Maximize PROTECTION (Model!B65): weighted share of threats defeated, SUM W_j D_j / SUM W_j R_j
A4: By changing | B4: QU grid Model!B35:G38 and QC grid Model!B108:G111 (interceptors at uncovered / Patriot-covered sites), BUILD_AEGIS Model!B41 and PATRIOT_BATTERIES Model!C41 (number of Patriot batteries). THAAD build is fixed at 1: the battery is already on Guam. Set OPTION (Model!B154) first.
A5: Engine | B5: GRG Nonlinear (the objective uses EXP, so Simplex LP cannot be used), with Multistart on. Integer optimality tolerance 0%. Not run in the build (Solver hangs headless).
A6: Constraint 1 | B6: QU and QC grids = integer; PATRIOT_BATTERIES = integer
A7: Constraint 2 | B7: QU and QC grids >= 0; PATRIOT_BATTERIES >= 0
A8: Constraint 3 | B8: BUILD_AEGIS = binary
A9: Constraint 4 | B9: TOTAL_SPEND (B57) <= BUDGET (B23); BUDGET = 8,000 for Table 2
A10: Constraint 5 | B10: TOTAL_SPEND (B57) >= SPEND_FLOOR (B58) = USE_MIN x BUDGET
A11: Constraint 6 | B11: AEGIS_CELL_SLACK (B61) >= 0 - shared Mk 41 cells, and no Standard Missiles without Aegis
A12: Constraint 7 | B12: PATRIOT_SLACK (B63) >= 0 - launcher space, and no PAC-3 without a Patriot battery
A13: Constraint 8 | B13: THAAD_SLACK (B64) >= 0
A14: Constraint 9 | B14: CAP_SLACK (B67:G67) >= 0 - production cap CAP x ALLOWED_NOW, so a type the OPTION does not allow cannot be bought
... A26: Constraint 16 | B26: MSE_FULL_SLACK (B167) = 0 - Option 1 loads every battery fully with MSE
